Workbook

Sheet emission data
A1: General information | J1: Application | O1: Slurry information | R1: Soil information | W1: Emission | AA1: Application notes
A2: Source | B2: Separation method | C2: Separation scale | D2: Slurry source | E2: Fraction | F2: FractionA | G2: Emission measuring method | H2: Duration (h) | I2: Set | J2: Application method | K2: Amount (ton/ha) | L2: Temperature at application (°C) | M2: Average temperature (°C) | N2: Precipitation during measurements (mm) | O2: Dry matter (%) | P2: pH | Q2: Total ammoniacal nitrogen (TAN) (g/kg) | R2: Type | S2: Clay content (%) | T2: Crop | U2: Dry bulk density (g/cm3) | V2: Gravimetric water content (g/g) | W2: Emission (% applied total ammoniacal nitrogen) | X2: Emission (% initial raw total ammoniacal nitrogen) | Y2: Source of emission data in original publication | Z2: Experiment ID in original publication | AA2: Notes
A3: source | B3: sep.meth | C3: sep.scale | D3: slurry.source | E3: frac.stud | F3: frac.studA | G3: meas.meth | H3: duration | I3: set | J3: app.meth | K3: amount | L3: temp.app | M3: temp.avg | N3: pres | O3: DM | P3: pH | Q3: TAN | R3: soil.type | S3: soil.clay | T3: crop | U3: soil.dens | V3: soil.water | W3: emis.perc | X3: emis.ini | Y3: emis.source | Z3: emis.ID | AA3: notes
A4: Amon et al. (2006) | C4: full | D4: cattle | E4: raw | F4: raw | G4: dynamic chambers | H4: 48 | I4: 1 | J4: trailing hose | K4: 40 | N4: 0 | O4: 5.7 | P4: 7.8 | Q4: 1.82 | T4: grass | W4: =(185.8/1000)/1.82*100 -> 10.208791 | Y4: Calculation based on Table 2 and 3. | Z4: Untreated and Separated | AA4: Only measurements for 48 h
A5: Amon et al. (2006) | B5: screw press | C5: full | D5: cattle | E5: lf | F5: lf | G5: dynamic chambers | H5: 48 | I5: 1 | J5: trailing hose | K5: 40 | N5: 0 | O5: 4.1 | P5: 7.88 | Q5: 1.73 | T5: grass | W5: =(75.8/1000)/1.73*100 -> 4.3815029 | Y5: Calculation based on Table 2 and 3. | Z5: Untreated and Separated | AA5: Only measurements for 48 h
A6: Amon et al. (2006) | B6: screw press | C6: full | D6: cattle | E6: sf | F6: sf | G6: dynamic chambers | I6: 1 | N6: 0
A7: Andersson et al. (2023) | C7: full | D7: cattle | E7: raw | F7: raw | G7: dynamic chambers | H7: 70 | I7: 1 | J7: trailing hose | K7: 35 | M7: 19.1 | N7: 0 | O7: 9 | P7: 6.8 | Q7: 1.9 | R7: silty clay | S7: 43 | T7: grass | U7: 1.05 | W7: 28.7 | Y7: Manuscript draft from K. Andersson 16 Sep 2021 to jp@bce.au.dk. | Z7: Experiment 4: Separated and Untreated
A8: Andersson et al. (2023) | B8: screw press | C8: full | D8: cattle | E8: lf | F8: lf | G8: dynamic chambers | H8: 70 | I8: 1 | J8: trailing hose | K8: 35 | M8: 20.1 | N8: 0 | O8: 4.6 | P8: 7.1 | Q8: 2 | R8: silty clay | S8: 43 | T8: grass | U8: 1.05 | W8: 23.1 | Y8: Manuscript draft from K. Andersson 16 Sep 2021 to jp@bce.au.dk. | Z8: Experiment 4: Separated and Untreated
A9: Balsari et al. (2008a) | C9: full | D9: pig | E9: raw | F9: raw | G9: dynamic chambers | H9: 120 | I9: 1 | J9: broadcast | K9: =70/4.3 -> 16.27907 | M9: 18.4 | N9: 0 | O9: 3.5 | P9: 7.8 | Q9: 3 | R9: loamy sand | T9: grass | W9: =21/0.7 -> 30 | Y9: Read of Fig. 2 | Z9: All three fractions, Schmidt tunnels with airflow of 0.6 m/s | AA9: Amounts (ton/ha) are calculated based on applicatoin rate of 70 kgN/ha and info in Table 1. Unsure if it should be TAN. Emission is calulated from read of Fig 2. and the TAN/TKN ratio in Table 1. Did not include data with air speed of ~0 m/s as it has been shown that static chambers are not usefull for NH3 measurements. Unknown application method, assumed broadcast.
A10: Balsari et al. (2008a) | B10: screw press | C10: full | D10: pig | E10: lf | F10: lf | G10: dynamic chambers | H10: 120 | I10: 1 | J10: broadcast | K10: =70/4 -> 17.5 | M10: 18.4 | N10: 0 | O10: 2.4 | P10: 8 | Q10: 3 | R10: loamy sand | T10: grass | W10: =14/0.75 -> 18.666667 | Y10: Read of Fig. 2 | Z10: All three fractions, Schmidt tunnels with airflow of 0.6 m/s | AA10: Amounts (ton/ha) are calculated based on applicatoin rate of 70 kgN/ha and info in Table 1. Unsure if it should be TAN. Emission is calulated from read of Fig 2. and the TAN/TKN ratio in Table 1. Did not include data with air speed of ~0 m/s as it has been shown that static chambers are not usefull for NH3 measurements. Unknown application method, assumed broadcast.
A11: Balsari et al. (2008a) | B11: screw press | C11: full | D11: pig | E11: sf | F11: sf | G11: dynamic chambers | H11: 120 | I11: 1 | J11: broadcast | K11: =70/7.2 -> 9.7222222 | M11: 18.4 | N11: 0 | O11: 23.2 | P11: 8.4 | Q11: 3.3 | R11: loamy sand | T11: grass | W11: =19/0.45 -> 42.222222 | Y11: Read of Fig. 2 | Z11: All three fractions, Schmidt tunnels with airflow of 0.6 m/s | AA11: Amounts (ton/ha) are calculated based on applicatoin rate of 70 kgN/ha and info in Table 1. Unsure if it should be TAN. Emission is calulated from read of Fig 2. and the TAN/TKN ratio in Table 1. Did not include data with air speed of ~0 m/s as it has been shown that static chambers are not usefull for NH3 measurements. Unknown application method, assumed broadcast.
A12: Balsari et al. (2008a) | C12: full | D12: pig | E12: raw | F12: raw | G12: dynamic chambers | H12: 120 | I12: 2 | J12: broadcast | K12: =70/3.6 -> 19.444444 | M12: 11.4 | N12: 0 | O12: 3.5 | P12: 7.8 | Q12: 2 | R12: loamy sand | T12: grass | W12: =23/0.56 -> 41.071429 | Y12: Read of Fig. 2 | Z12: All three fractions, Schmidt tunnels with airflow of 0.6 m/s | AA12: Amounts (ton/ha) are calculated based on applicatoin rate of 70 kgN/ha and info in Table 1. Unsure if it should be TAN. Emission is calulated from read of Fig 2. and the TAN/TKN ratio in Table 1. Did not include data with air speed of ~0 m/s as it has been shown that static chambers are not usefull for NH3 measurements. Unknown application method, assumed broadcast.
A13: Balsari et al. (2008a) | B13: screw press | C13: full | D13: pig | E13: lf | F13: lf | G13: dynamic chambers | H13: 120 | I13: 2 | J13: broadcast | K13: =70/3.2 -> 21.875 | M13: 11.4 | N13: 0 | O13: 2.1 | P13: 7.8 | Q13: 2.1 | R13: loamy sand | T13: grass | W13: =12/0.66 -> 18.181818 | Y13: Read of Fig. 2 | Z13: All three fractions, Schmidt tunnels with airflow of 0.6 m/s | AA13: Amounts (ton/ha) are calculated based on applicatoin rate of 70 kgN/ha and info in Table 1. Unsure if it should be TAN. Emission is calulated from read of Fig 2. and the TAN/TKN ratio in Table 1. Did not include data with air speed of ~0 m/s as it has been shown that static chambers are not usefull for NH3 measurements. Unknown application method, assumed broadcast.
A14: Balsari et al. (2008a) | B14: screw press | C14: full | D14: pig | E14: sf | F14: sf | G14: dynamic chambers | H14: 120 | I14: 2 | J14: broadcast | K14: =70/6.8 -> 10.294118 | M14: 11.4 | N14: 0 | O14: 28.9 | P14: 8.2 | Q14: 2.5 | R14: loamy sand | T14: grass | W14: =18/0.37 -> 48.648649 | Y14: Read of Fig. 2 | Z14: All three fractions, Schmidt tunnels with airflow of 0.6 m/s | AA14: Amounts (ton/ha) are calculated based on applicatoin rate of 70 kgN/ha and info in Table 1. Unsure if it should be TAN. Emission is calulated from read of Fig 2. and the TAN/TKN ratio in Table 1. Did not include data with air speed of ~0 m/s as it has been shown that static chambers are not usefull for NH3 measurements. Unknown application method, assumed broadcast.
A15: Balsari et al. (2008b) | C15: full | D15: cattle | E15: raw | F15: raw | G15: dynamic chambers | H15: 120 | I15: 1 | J15: broadcast | K15: =70/3.5 -> 20 | M15: 27.8 | N15: 0 | O15: 5.7 | P15: 7.6 | Q15: 2.1 | R15: loamy sand | T15: grass | W15: =35.2/0.6 -> 58.666667 | Y15: Table 3 | Z15: All three fractions, Schmidt tunnels with airflow of 0.6 m/s | AA15: Amounts (ton/ha) are calculated based on applicatoin rate of 70 kgN/ha and info in Table 2. Unsure if it should be TAN. Emission is calulated from data in Table 3. and the TAN/TKN ratio in Table 2. Did not include data with air speed of ~0 m/s as it has been shown that static chambers are not usefull for NH3 measurements. Unknown application method, assumed broadcast.
A16: Balsari et al. (2008b) | B16: screw press | C16: full | D16: cattle | E16: lf | F16: lf | G16: dynamic chambers | H16: 120 | I16: 1 | J16: broadcast | K16: =70/3.3 -> 21.212121 | M16: 27.8 | N16: 0 | O16: 4.4 | P16: 7.8 | Q16: 2.1 | R16: loamy sand | T16: grass | W16: =32.3/0.64 -> 50.46875 | Y16: Table 3 | Z16: All three fractions, Schmidt tunnels with airflow of 0.6 m/s | AA16: Amounts (ton/ha) are calculated based on applicatoin rate of 70 kgN/ha and info in Table 2. Unsure if it should be TAN. Emission is calulated from data in Table 3. and the TAN/TKN ratio in Table 2. Did not include data with air speed of ~0 m/s as it has been shown that static chambers are not usefull for NH3 measurements. Unknown application method, assumed broadcast.
A17: Balsari et al. (2008b) | B17: screw press | C17: full | D17: cattle | E17: sf | F17: sf | G17: dynamic chambers | H17: 120 | I17: 1 | J17: broadcast | K17: =70/5.1 -> 13.72549 | M17: 27.8 | N17: 0 | O17: 22.8 | P17: 8.7 | Q17: 1.8 | R17: loamy sand | T17: grass | W17: =16.9/0.36 -> 46.944444 | Y17: Table 3 | Z17: All three fractions, Schmidt tunnels with airflow of 0.6 m/s | AA17: Amounts (ton/ha) are calculated based on applicatoin rate of 70 kgN/ha and info in Table 2. Unsure if it should be TAN. Emission is calulated from data in Table 3. and the TAN/TKN ratio in Table 2. Did not include data with air speed of ~0 m/s as it has been shown that static chambers are not usefull for NH3 measurements. Unknown application method, assumed broadcast.
A18: Balsari et al. (2008b) | C18: full | D18: cattle | E18: raw | F18: raw | G18: dynamic chambers | H18: 120 | I18: 2 | J18: broadcast | K18: =70/3.4 -> 20.588235 | M18: 12.5 | N18: 0 | O18: 7.1 | P18: 7.5 | Q18: 1.5 | R18: loamy sand | T18: grass | W18: =23.2/0.44 -> 52.727273 | Y18: Table 3 | Z18: All three fractions, Schmidt tunnels with airflow of 0.6 m/s | AA18: Amounts (ton/ha) are calculated based on applicatoin rate of 70 kgN/ha and info in Table 2. Unsure if it should be TAN. Emission is calulated from data in Table 3. and the TAN/TKN ratio in Table 2. Did not include data with air speed of ~0 m/s as it has been shown that static chambers are not usefull for NH3 measurements. Unknown application method, assumed broadcast.
A19: Balsari et al. (2008b) | B19: screw press | C19: full | D19: cattle | E19: lf | F19: lf | G19: dynamic chambers | H19: 120 | I19: 2 | J19: broadcast | K19: =70/3.2 -> 21.875 | M19: 12.5 | N19: 0 | O19: 4.4 | P19: 7.8 | Q19: 1.7 | R19: loamy sand | T19: grass | W19: =17.5/0.53 -> 33.018868 | Y19: Table 3 | Z19: All three fractions, Schmidt tunnels with airflow of 0.6 m/s | AA19: Amounts (ton/ha) are calculated based on applicatoin rate of 70 kgN/ha and info in Table 2. Unsure if it should be TAN. Emission is calulated from data in Table 3. and the TAN/TKN ratio in Table 2. Did not include data with air speed of ~0 m/s as it has been shown that static chambers are not usefull for NH3 measurements. Unknown application method, assumed broadcast.
A20: Balsari et al. (2008b) | B20: screw press | C20: full | D20: cattle | E20: sf | F20: sf | G20: dynamic chambers | H20: 120 | I20: 2 | J20: broadcast | K20: =70/4.7 -> 14.893617 | M20: 12.5 | N20: 0 | O20: 20.9 | P20: 8.2 | Q20: 1.4 | R20: loamy sand | T20: grass | W20: =13.7/0.3 -> 45.666667 | Y20: Table 3 | Z20: All three fractions, Schmidt tunnels with airflow of 0.6 m/s | AA20: Amounts (ton/ha) are calculated based on applicatoin rate of 70 kgN/ha and info in Table 2. Unsure if it should be TAN. Emission is calulated from data in Table 3. and the TAN/TKN ratio in Table 2. Did not include data with air speed of ~0 m/s as it has been shown that static chambers are not usefull for NH3 measurements. Unknown application method, assumed broadcast.
A21: Bhandral et al. (2009) | C21: full | D21: cattle | E21: raw | F21: raw | G21: dynamic chambers | H21: 264 | I21: 1 | J21: broadcast | K21: 100 | N21: 0 | O21: 6.8 | P21: 6.8 | Q21: 1.3 | R21: silty to sandy loam | T21: none | U21: 1.09 | V21: 0.31 | W21: 37.5 | Y21: Table 3 | Z21: All experiments | AA21: Duration is minimum 11 days = 264 h, the longest exp was 15 d.
A22: Bhandral et al. (2009) | B22: decanter | C22: full | D22: cattle | E22: lf | F22: lf | G22: dynamic chambers | H22: 264 | I22: 1 | J22: broadcast | K22: 120 | N22: 0 | O22: 2.8 | P22: 7 | Q22: 1.2 | R22: silty to sandy loam | T22: none | U22: 1.09 | W22: 39.2 | Y22: Table 3 | Z22: All experiments | AA22: Duration is minimum 11 days = 264 h, the longest exp was 15 d.
A23: Bhandral et al. (2009) | C23: full | D23: cattle | E23: raw | F23: raw | G23: dynamic chambers | H23: 264 | I23: 2 | J23: broadcast | K23: 104 | N23: 0 | O23: 7.2 | P23: 6.8 | Q23: 1.2 | R23: silty to sandy loam | T23: none | U23: 1.09 | V23: 0.36 | W23: 39.3 | Y23: Table 3 | Z23: All experiments | AA23: Duration is minimum 11 days = 264 h, the longest exp was 15 d.
A24: Bhandral et al. (2009) | B24: decanter | C24: full | D24: cattle | E24: lf | F24: lf | G24: dynamic chambers | H24: 264 | I24: 2 | J24: broadcast | K24: 126 | N24: 0 | O24: 2.2 | P24: 7.4 | Q24: 1.1 | R24: silty to sandy loam | T24: none | U24: 1.09 | W24: 38 | Y24: Table 3 | Z24: All experiments | AA24: Duration is minimum 11 days = 264 h, the longest exp was 15 d.
A25: Bhandral et al. (2009) | C25: full | D25: cattle | E25: raw | F25: raw | G25: dynamic chambers | H25: 264 | I25: 3 | J25: broadcast | K25: 109 | N25: 0 | O25: 7 | P25: 7.5 | Q25: 1.1 | R25: silty to sandy loam | T25: none | U25: 1.09 | V25: 0.33 | W25: 36.7 | Y25: Table 3 | Z25: All experiments | AA25: Duration is minimum 11 days = 264 h, the longest exp was 15 d.
A26: Bhandral et al. (2009) | B26: decanter | C26: full | D26: cattle | E26: lf | F26: lf | G26: dynamic chambers | H26: 264 | I26: 3 | J26: broadcast | K26: 133 | N26: 0 | O26: 1.3 | P26: 8.1 | Q26: 1 | R26: silty to sandy loam | T26: none | U26: 1.09 | W26: 51 | Y26: Table 3 | Z26: All experiments | AA26: Duration is minimum 11 days = 264 h, the longest exp was 15 d.
A27: Bhandral et al. (2009) | C27: full | D27: cattle | E27: raw | F27: raw | G27: dynamic chambers | H27: 264 | I27: 4 | J27: broadcast | K27: 115 | N27: 0 | O27: 6 | Q27: 1 | R27: silty to sandy loam | T27: none | U27: 1.09 | V27: 0.26 | W27: 37.4 | Y27: Table 3 | Z27: All experiments | AA27: Duration is minimum 11 days = 264 h, the longest exp was 15 d.
A28: Bhandral et al. (2009) | B28: decanter | C28: full | D28: cattle | E28: lf | F28: lf | G28: dynamic chambers | H28: 264 | I28: 4 | J28: broadcast | K28: 124 | N28: 0 | O28: 2.8 | Q28: 0.9 | R28: silty to sandy loam | T28: none | U28: 1.09 | W28: 39.1 | Y28: Table 3 | Z28: All experiments | AA28: Duration is minimum 11 days = 264 h, the longest exp was 15 d.
A29: Bhandral et al. (2009) | C29: full | D29: cattle | E29: raw | F29: raw | G29: dynamic chambers | H29: 264 | I29: 5 | J29: broadcast | K29: 120 | N29: 0 | O29: 5.7 | Q29: 1 | R29: silty to sandy loam | T29: none | U29: 1.09 | V29: 0.37 | W29: 39.1 | Y29: Table 3 | Z29: All experiments | AA29: Duration is minimum 11 days = 264 h, the longest exp was 15 d.
A30: Bhandral et al. (2009) | B30: decanter | C30: full | D30: cattle | E30: lf | F30: lf | G30: dynamic chambers | H30: 264 | I30: 5 | J30: broadcast | K30: 141 | N30: 0 | O30: 2 | Q30: 0.9 | R30: silty to sandy loam | T30: none | U30: 1.09 | W30: 16.3 | Y30: Table 3 | Z30: All experiments | AA30: Duration is minimum 11 days = 264 h, the longest exp was 15 d.
A31: Bhandral et al. (2009) | C31: full | D31: cattle | E31: raw | F31: raw | G31: dynamic chambers | H31: 264 | I31: 6 | J31: broadcast | K31: 70 | N31: 0 | O31: 4.6 | Q31: 1 | R31: silty to sandy loam | T31: none | U31: 1.09 | V31: 0.33 | W31: 41.9 | Y31: Table 3 | Z31: All experiments | AA31: Duration is minimum 11 days = 264 h, the longest exp was 15 d.
A32: Bhandral et al. (2009) | B32: decanter | C32: full | D32: cattle | E32: lf | F32: lf | G32: dynamic chambers | H32: 264 | I32: 6 | J32: broadcast | K32: 127 | N32: 0 | O32: 1.3 | Q32: 0.6 | R32: silty to sandy loam | T32: none | U32: 1.09 | W32: 13.4 | Y32: Table 3 | Z32: All experiments | AA32: Duration is minimum 11 days = 264 h, the longest exp was 15 d.
A33: Bhandral et al. (2009) | C33: full | D33: cattle | E33: raw | F33: raw | G33: dynamic chambers | H33: 264 | I33: 1 | J33: band spread on slots | K33: 100 | N33: 0 | O33: 6.8 | P33: 6.8 | Q33: 1.3 | R33: silty to sandy loam | T33: none | U33: 1.09 | V33: 0.31 | W33: 24.6 | Y33: Table 3 | Z33: All experiments | AA33: Duration is minimum 11 days = 264 h, the longest exp was 15 d.
A34: Bhandral et al. (2009) | B34: decanter | C34: full | D34: cattle | E34: lf | F34: lf | G34: dynamic chambers | H34: 264 | I34: 1 | J34: band spread on slots | K34: 120 | N34: 0 | O34: 2.8 | P34: 7 | Q34: 1.2 | R34: silty to sandy loam | T34: none | U34: 1.09 | V34: 0.31 | W34: 14.9 | Y34: Table 3 | Z34: All experiments | AA34: Duration is minimum 11 days = 264 h, the longest exp was 15 d.
A35: Bhandral et al. (2009) | C35: full | D35: cattle | E35: raw | F35: raw | G35: dynamic chambers | H35: 264 | I35: 2 | J35: band spread on slots | K35: 104 | N35: 0 | O35: 7.2 | P35: 6.8 | Q35: 1.2 | R35: silty to sandy loam | T35: none | U35: 1.09 | V35: 0.36 | W35: 24.1 | Y35: Table 3 | Z35: All experiments | AA35: Duration is minimum 11 days = 264 h, the longest exp was 15 d.
A36: Bhandral et al. (2009) | B36: decanter | C36: full | D36: cattle | E36: lf | F36: lf | G36: dynamic chambers | H36: 264 | I36: 2 | J36: band spread on slots | K36: 126 | N36: 0 | O36: 2.2 | P36: 7.4 | Q36: 1.1 | R36: silty to sandy loam | T36: none | U36: 1.09 | V36: 0.36 | W36: 17.9 | Y36: Table 3 | Z36: All experiments | AA36: Duration is minimum 11 days = 264 h, the longest exp was 15 d.
A37: Bhandral et al. (2009) | C37: full | D37: cattle | E37: raw | F37: raw | G37: dynamic chambers | H37: 264 | I37: 3 | J37: band spread on slots | K37: 109 | N37: 0 | O37: 7 | P37: 7.5 | Q37: 1.1 | R37: silty to sandy loam | T37: none | U37: 1.09 | V37: 0.33 | W37: 25.1 | Y37: Table 3 | Z37: All experiments | AA37: Duration is minimum 11 days = 264 h, the longest exp was 15 d.
A38: Bhandral et al. (2009) | B38: decanter | C38: full | D38: cattle | E38: lf | F38: lf | G38: dynamic chambers | H38: 264 | I38: 3 | J38: band spread on slots | K38: 133 | N38: 0 | O38: 1.3 | P38: 8.1 | Q38: 1 | R38: silty to sandy loam | T38: none | U38: 1.09 | V38: 0.33 | W38: 28.2 | Y38: Table 3 | Z38: All experiments | AA38: Duration is minimum 11 days = 264 h, the longest exp was 15 d.
A39: Bhandral et al. (2009) | C39: full | D39: cattle | E39: raw | F39: raw | G39: dynamic chambers | H39: 264 | I39: 4 | J39: band spread on slots | K39: 115 | N39: 0 | O39: 6 | Q39: 1 | R39: silty to sandy loam | T39: none | U39: 1.09 | V39: 0.26 | W39: 23.5 | Y39: Table 3 | Z39: All experiments | AA39: Duration is minimum 11 days = 264 h, the longest exp was 15 d.
A40: Bhandral et al. (2009) | B40: decanter | C40: full | D40: cattle | E40: lf | F40: lf | G40: dynamic chambers | H40: 264 | I40: 4 | J40: band spread on slots | K40: 124 | N40: 0 | O40: 2.8 | Q40: 0.9 | R40: silty to sandy loam | T40: none | U40: 1.09 | V40: 0.26 | W40: 28.6 | Y40: Table 3 | Z40: All experiments | AA40: Duration is minimum 11 days = 264 h, the longest exp was 15 d.
...

Sheet separation efficiency data
A1: General info | F1: Separation efficiency | J1: Samples | M1: Notes
A2: Source | B2: Separation method | C2: Slurry source | D2: Fraction studied | E2: Set | F2: Dry matter separation efficiency (%) | G2: Total ammoniacal nitrogen (TAN) separation efficiency (%) | H2: % mass after separation | I2: Separation efficiency source in original publication | J2: Dry matter (%) | K2: pH | L2: Total ammoniacal nitrogen (TAN) (g/kg) | M2: Notes
A3: source | B3: sep.meth | C3: slurry.source | D3: frac | E3: set | F3: DM.sep.eff | G3: TAN.sep.eff | H3: Mass.sep.eff | I3: sep.eff.source | J3: DM | K3: pH | L3: TAN | M3: Notes
A4: Aguirre-Villegas et al. (2019) | B4: screw press | C4: digestate | D4: raw | E4: 1 | J4: 5.3 | L4: =34.2*J4/100 -> 1.8126 | M4: Farm 1
A5: Aguirre-Villegas et al. (2019) | B5: screw press | C5: digestate | D5: lf | E5: 1 | F5: =J5*H5/J4 -> 67.963836 | G5: =L5*H5/L4 -> 107.90749 | H5: =(J4-J6)/(J5-J6)*100 -> 94.791667 | J5: 3.8 | L5: =54.3*J5/100 -> 2.0634 | M5: Farm 1
A6: Aguirre-Villegas et al. (2019) | B6: screw press | C6: digestate | D6: sf | E6: 1 | F6: =J6*H6/J4 -> 32.036164 | G6: =L6*H6/L4 -> 0.28101898 | H6: =100-H5 -> 5.2083333 | J6: 32.6 | L6: =0.3*J6/100 -> 0.0978 | M6: Farm 1
A7: Aguirre-Villegas et al. (2019) | B7: screw press | C7: cattle | D7: raw | E7: 2 | J7: 7.9 | L7: =19.3*J7/100 -> 1.5247 | M7: Farm 2
A8: Aguirre-Villegas et al. (2019) | B8: screw press | C8: cattle | D8: lf | E8: 2 | F8: =J8*H8/J7 -> 52.906136 | G8: =L8*H8/L7 -> 83.608143 | H8: =(J7-J9)/(J8-J9)*100 -> 88.927336 | J8: 4.7 | L8: =30.5*J8/100 -> 1.4335 | M8: Farm 2
A9: Aguirre-Villegas et al. (2019) | B9: screw press | C9: cattle | D9: sf | E9: 2 | F9: =J9*H9/J7 -> 47.093864 | G9: =L9*H9/L7 -> 0.24400966 | H9: =100-H8 -> 11.072664 | J9: 33.6 | L9: =0.1*J9/100 -> 0.0336 | M9: Farm 2
A10: Aguirre-Villegas et al. (2019) | B10: screw press | C10: digestate | D10: raw | E10: 3 | J10: 8 | L10: =27.9*J10/100 -> 2.232 | M10: Farm 3
A11: Aguirre-Villegas et al. (2019) | B11: screw press | C11: digestate | D11: lf | E11: 3 | F11: =J11*H11/J10 -> 41.586022 | G11: =L11*H11/L10 -> 84.960689 | H11: =(J10-J12)/(J11-J12)*100 -> 85.304659 | J11: 3.9 | L11: =57*J11/100 -> 2.223 | M11: Farm 3
A12: Aguirre-Villegas et al. (2019) | B12: screw press | C12: digestate | D12: sf | E12: 3 | F12: =J12*H12/J10 -> 58.413978 | G12: =L12*H12/L10 -> 1.0468455 | H12: =100-H11 -> 14.695341 | J12: 31.8 | L12: =0.5*J12/100 -> 0.159 | M12: Farm 3
A13: Aguirre-Villegas et al. (2019) | B13: screw press | C13: digestate | D13: raw | E13: 4 | J13: 5 | L13: =37.2*J13/100 -> 1.86 | M13: Farm 4
A14: Aguirre-Villegas et al. (2019) | B14: screw press | C14: digestate | D14: lf | E14: 4 | F14: =J14*H14/J13 -> 58.88 | G14: =L14*H14/L13 -> 8.9586237 | H14: =(J13-J15)/(J14-J15)*100 -> 92 | J14: 3.2 | L14: =56.6*J14/1000 -> 0.18112 | M14: Farm 4
A15: Aguirre-Villegas et al. (2019) | B15: screw press | C15: digestate | D15: sf | E15: 4 | F15: =J15*H15/J13 -> 41.12 | G15: =L15*H15/L13 -> 0.3316129 | H15: =100-H14 -> 8 | J15: 25.7 | L15: =0.3*J15/100 -> 0.0771 | M15: Farm 4
A16: Aguirre-Villegas et al. (2019) | B16: screw press | C16: digestate | D16: raw | E16: 5 | J16: 4.9 | L16: =49.5*J16/100 -> 2.4255 | M16: Farm 5
A17: Aguirre-Villegas et al. (2019) | B17: screw press | C17: digestate | D17: lf | E17: 5 | F17: =J17*H17/J16 -> 63.202512 | G17: =L17*H17/L16 -> 108.2742 | H17: =(J16-J18)/(J17-J18)*100 -> 93.846154 | J17: 3.3 | L17: =84.8*J17/100 -> 2.7984 | M17: Farm 5
A18: Aguirre-Villegas et al. (2019) | B18: screw press | C18: digestate | D18: sf | E18: 5 | F18: =J18*H18/J16 -> 36.797488 | G18: =L18*H18/L16 -> 0.44603016 | H18: =100-H17 -> 6.1538462 | J18: 29.3 | L18: =0.6*J18/100 -> 0.1758 | M18: Farm 5
A19: Aguirre-Villegas et al. (2019) | B19: screw press | C19: digestate | D19: raw | E19: 6 | J19: 4.9 | L19: =31.4*J19/100 -> 1.5386 | M19: Farm 6
A20: Aguirre-Villegas et al. (2019) | B20: screw press | C20: digestate | D20: lf | E20: 6 | F20: =J20*H20/J19 -> 63.498542 | G20: =L20*H20/L19 -> 85.945479 | H20: =(J19-J21)/(J20-J21)*100 -> 94.285714 | J20: 3.3 | L20: =42.5*J20/100 -> 1.4025 | M20: Farm 6
A21: Aguirre-Villegas et al. (2019) | B21: screw press | C21: digestate | D21: sf | E21: 6 | F21: =J21*H21/J19 -> 36.501458 | G21: =L21*H21/L19 -> 0.23249336 | H21: =100-H20 -> 5.7142857 | J21: 31.3 | L21: =0.2*J21/100 -> 0.0626 | M21: Farm 6
A22: Aguirre-Villegas et al. (2019) | B22: screw press | C22: digestate | D22: raw | E22: 7 | J22: 5.9 | L22: =40.2*J22/100 -> 2.3718 | M22: Farm 7
A23: Aguirre-Villegas et al. (2019) | B23: screw press | C23: digestate | D23: lf | E23: 7 | F23: =J23*H23/J22 -> 60.499856 | G23: =L23*H23/L22 -> 90.749785 | H23: =(J22-J24)/(J23-J24)*100 -> 91.525424 | J23: 3.9 | L23: =60.3*J23/100 -> 2.3517 | M23: Farm 7
A24: Aguirre-Villegas et al. (2019) | B24: screw press | C24: digestate | D24: sf | E24: 7 | F24: =J24*H24/J22 -> 39.500144 | G24: =L24*H24/L22 -> 0.29477719 | H24: =100-H23 -> 8.4745763 | J24: 27.5 | L24: =0.3*J24/100 -> 0.0825 | M24: Farm 7
A25: Aguirre-Villegas et al. (2019) | B25: centrifuge | C25: digestate | D25: raw | E25: 8 | J25: 4.6 | L25: =48.2*J25/100 -> 2.2172 | M25: Farm 8
A26: Aguirre-Villegas et al. (2019) | B26: centrifuge | C26: digestate | D26: lf | E26: 8 | F26: =J26*H26/J25 -> 56.451613 | G26: =L26*H26/L25 -> 82.10079 | H26: =(J25-J27)/(J26-J27)*100 -> 92.741935 | J26: 2.8 | L26: =70.1*J26/100 -> 1.9628 | M26: Farm 8
A27: Aguirre-Villegas et al. (2019) | B27: centrifuge | C27: digestate | D27: sf | E27: 8 | F27: =J27*H27/J25 -> 43.548387 | G27: =L27*H27/L25 -> 0.5420961 | H27: =(J25-J26)/(J27-J26)*100 -> 7.2580645 | J27: 27.6 | L27: =0.6*J27/100 -> 0.1656 | M27: Farm 8
A28: Aguirre-Villegas et al. (2019) | B28: screw press | C28: cattle | D28: raw | E28: 9 | J28: 9.7 | L28: =19.5*J28/100 -> 1.8915 | M28: Farm 9
A29: Aguirre-Villegas et al. (2019) | B29: screw press | C29: cattle | D29: lf | E29: 9 | F29: =J29*H29/J28 -> 52.343467 | G29: =L29*H29/L28 -> 71.133429 | H29: =(J28-J30)/(J29-J30)*100 -> 87.539936 | J29: 5.8 | L29: =26.5*J29/100 -> 1.537 | M29: Farm 9
A30: Aguirre-Villegas et al. (2019) | B30: screw press | C30: cattle | D30: sf | E30: 9 | F30: =J30*H30/J28 -> 47.656533 | G30: =L30*H30/L28 -> 0.17107473 | H30: =(J28-J29)/(J30-J29)*100 -> 12.460064 | J30: 37.1 | L30: =0.07*J30/100 -> 0.02597 | M30: Farm 9
A31: Amon et al. (2006) | B31: screw press | C31: cattle | D31: raw | E31: 1 | J31: 9.24 | L31: 1.57
A32: Amon et al. (2006) | B32: screw press | C32: cattle | D32: lf | E32: 1 | F32: =J32*H32/J31 -> 50.497098 | G32: =L32*H32/L31 -> 73.676014 | H32: =(J31-J33)/(J32-J33)*100 -> 78.156313 | J32: 5.97 | L32: 1.48
A33: Amon et al. (2006) | B33: screw press | C33: cattle | D33: sf | E33: 1 | F33: =J33*H33/J31 -> 49.502902 | G33: =L33*H33/L31 -> 12.939254 | H33: =100-H32 -> 21.843687 | J33: 20.94 | L33: 0.93
A34: Anderson et al, in prep | B34: screw press | C34: cattle | D34: raw | E34: 1 | J34: ='emission data'!O7 -> 9 | K34: ='emission data'!P7 -> 6.8 | L34: ='emission data'!Q7 -> 1.9
A35: Anderson et al, in prep | B35: screw press | C35: cattle | D35: lf | E35: 1 | F35: =J35*H35/J34 -> 43.71345 | G35: =L35*H35/L34 -> 90.027701 | H35: =(J34-35)/(J35-35)*100 -> 85.526316 | J35: ='emission data'!O8 -> 4.6 | K35: ='emission data'!P8 -> 7.1 | L35: ='emission data'!Q8 -> 2
A36: Bachmann et al. (2016) | B36: screw press | C36: digestate | D36: raw | E36: 1 | J36: =(6.97+6.64)/2 -> 6.805 | K36: =(7.5+7.9)/2 -> 7.7 | L36: =(51+50)/2 -> 50.5
A37: Bachmann et al. (2016) | B37: screw press | C37: digestate | D37: lf | E37: 1 | F37: 65 | G37: 85 | H37: 92 | I37: From Fig. 1 | J37: =(4.89+4.8)/2 -> 4.845 | K37: =(8+7.8)/2 -> 7.9 | L37: =(53+53)/2 -> 53
A38: Bachmann et al. (2016) | B38: screw press | C38: digestate | D38: sf | E38: 1 | F38: 40 | G38: 10 | H38: 8 | I38: From Fig. 1 | J38: =(34.6+32.7)/2 -> 33.65 | K38: =(9+8.9)/2 -> 8.95 | L38: =(29+41)/2 -> 35
A39: Bauer et al. (2009) | B39: screw press | C39: digestate | D39: raw | E39: 1
A40: Bauer et al. (2009) | B40: screw press | C40: digestate | D40: lf | E40: 1 | F40: 38.2 | H40: 79.2 | M40: data is pooled for screw press and rotary screen separator in the paper
...
